<?xml version="1.0" encoding="UTF-8"?>
<!-- Generated by org.testng.reporters.JUnitReportReporter -->
<testsuite skipped="0" hostname="Aspire1698" name="com.sheplers.testscripts.productsection.ProductReviewSection" tests="9" failures="4" timestamp="28 Jul 2017 23:49:50 GMT" time="562.091" errors="0">
  <testcase name="TC_SHEPLERS_PRS_004" time="51.236" classname="com.sheplers.testscripts.productsection.ProductReviewSection"/>
  <testcase name="TC_SHEPLERS_PRS_007" time="66.766" classname="com.sheplers.testscripts.productsection.ProductReviewSection"/>
  <testcase name="TC_SHEPLERS_PRS_003" time="54.663" classname="com.sheplers.testscripts.productsection.ProductReviewSection">
    <failure type="java.lang.AssertionError" message="5. Rating Snapshot is not displayed as expected, plz check the event log">
      <![CDATA[java.lang.AssertionError: 5. Rating Snapshot is not displayed as expected, plz check the event log
	at org.testng.Assert.fail(Assert.java:93)
	at com.sheplers.support.Log.fail(Log.java:514)
	at com.sheplers.support.Log.assertThat(Log.java:692)
	at com.sheplers.testscripts.productsection.ProductReviewSection.TC_SHEPLERS_PRS_003(ProductReviewSection.java:224)
	at sun.reflect.NativeMethodAccessorImpl.invoke0(Native Method)
	at sun.reflect.NativeMethodAccessorImpl.invoke(Unknown Source)
	at sun.reflect.DelegatingMethodAccessorImpl.invoke(Unknown Source)
	at java.lang.reflect.Method.invoke(Unknown Source)
	at org.testng.internal.MethodInvocationHelper.invokeMethod(MethodInvocationHelper.java:108)
	at org.testng.internal.Invoker.invokeMethod(Invoker.java:661)
	at org.testng.internal.Invoker.invokeTestMethod(Invoker.java:869)
	at org.testng.internal.TestMethodWithDataProviderMethodWorker.call(TestMethodWithDataProviderMethodWorker.java:75)
	at org.testng.internal.TestMethodWithDataProviderMethodWorker.call(TestMethodWithDataProviderMethodWorker.java:14)
	at java.util.concurrent.FutureTask.run(Unknown Source)
	at java.util.concurrent.Executors$RunnableAdapter.call(Unknown Source)
	at java.util.concurrent.FutureTask.run(Unknown Source)
	at java.util.concurrent.ThreadPoolExecutor.runWorker(Unknown Source)
	at java.util.concurrent.ThreadPoolExecutor$Worker.run(Unknown Source)
	at java.lang.Thread.run(Unknown Source)
]]>
    </failure>
  </testcase> <!-- TC_SHEPLERS_PRS_003 -->
  <testcase name="TC_SHEPLERS_PRS_001" time="60.977" classname="com.sheplers.testscripts.productsection.ProductReviewSection">
    <failure type="java.lang.AssertionError" message="5. Product Reviews section is not displayed as expected, plz check the event log">
      <![CDATA[java.lang.AssertionError: 5. Product Reviews section is not displayed as expected, plz check the event log
	at org.testng.Assert.fail(Assert.java:93)
	at com.sheplers.support.Log.fail(Log.java:514)
	at com.sheplers.support.Log.assertThat(Log.java:692)
	at com.sheplers.testscripts.productsection.ProductReviewSection.TC_SHEPLERS_PRS_001(ProductReviewSection.java:87)
	at sun.reflect.NativeMethodAccessorImpl.invoke0(Native Method)
	at sun.reflect.NativeMethodAccessorImpl.invoke(Unknown Source)
	at sun.reflect.DelegatingMethodAccessorImpl.invoke(Unknown Source)
	at java.lang.reflect.Method.invoke(Unknown Source)
	at org.testng.internal.MethodInvocationHelper.invokeMethod(MethodInvocationHelper.java:108)
	at org.testng.internal.Invoker.invokeMethod(Invoker.java:661)
	at org.testng.internal.Invoker.invokeTestMethod(Invoker.java:869)
	at org.testng.internal.TestMethodWithDataProviderMethodWorker.call(TestMethodWithDataProviderMethodWorker.java:75)
	at org.testng.internal.TestMethodWithDataProviderMethodWorker.call(TestMethodWithDataProviderMethodWorker.java:14)
	at java.util.concurrent.FutureTask.run(Unknown Source)
	at java.util.concurrent.Executors$RunnableAdapter.call(Unknown Source)
	at java.util.concurrent.FutureTask.run(Unknown Source)
	at java.util.concurrent.ThreadPoolExecutor.runWorker(Unknown Source)
	at java.util.concurrent.ThreadPoolExecutor$Worker.run(Unknown Source)
	at java.lang.Thread.run(Unknown Source)
]]>
    </failure>
  </testcase> <!-- TC_SHEPLERS_PRS_001 -->
  <testcase name="TC_SHEPLERS_PRS_009" time="74.078" classname="com.sheplers.testscripts.productsection.ProductReviewSection"/>
  <testcase name="TC_SHEPLERS_PRS_008" time="68.132" classname="com.sheplers.testscripts.productsection.ProductReviewSection"/>
  <testcase name="TC_SHEPLERS_PRS_005" time="51.594" classname="com.sheplers.testscripts.productsection.ProductReviewSection">
    <failure type="java.lang.AssertionError" message="5. Customer reviews is not displayed as expected, plz check the event log">
      <![CDATA[java.lang.AssertionError: 5. Customer reviews is not displayed as expected, plz check the event log
	at org.testng.Assert.fail(Assert.java:93)
	at com.sheplers.support.Log.fail(Log.java:514)
	at com.sheplers.support.Log.assertThat(Log.java:692)
	at com.sheplers.testscripts.productsection.ProductReviewSection.TC_SHEPLERS_PRS_005(ProductReviewSection.java:357)
	at sun.reflect.NativeMethodAccessorImpl.invoke0(Native Method)
	at sun.reflect.NativeMethodAccessorImpl.invoke(Unknown Source)
	at sun.reflect.DelegatingMethodAccessorImpl.invoke(Unknown Source)
	at java.lang.reflect.Method.invoke(Unknown Source)
	at org.testng.internal.MethodInvocationHelper.invokeMethod(MethodInvocationHelper.java:108)
	at org.testng.internal.Invoker.invokeMethod(Invoker.java:661)
	at org.testng.internal.Invoker.invokeTestMethod(Invoker.java:869)
	at org.testng.internal.TestMethodWithDataProviderMethodWorker.call(TestMethodWithDataProviderMethodWorker.java:75)
	at org.testng.internal.TestMethodWithDataProviderMethodWorker.call(TestMethodWithDataProviderMethodWorker.java:14)
	at java.util.concurrent.FutureTask.run(Unknown Source)
	at java.util.concurrent.Executors$RunnableAdapter.call(Unknown Source)
	at java.util.concurrent.FutureTask.run(Unknown Source)
	at java.util.concurrent.ThreadPoolExecutor.runWorker(Unknown Source)
	at java.util.concurrent.ThreadPoolExecutor$Worker.run(Unknown Source)
	at java.lang.Thread.run(Unknown Source)
]]>
    </failure>
  </testcase> <!-- TC_SHEPLERS_PRS_005 -->
  <testcase name="TC_SHEPLERS_PRS_002" time="64.315" classname="com.sheplers.testscripts.productsection.ProductReviewSection">
    <failure type="java.lang.AssertionError" message="5. Average rating for the product with reviews is not displayed as expected, plz check the event log">
      <![CDATA[java.lang.AssertionError: 5. Average rating for the product with reviews is not displayed as expected, plz check the event log
	at org.testng.Assert.fail(Assert.java:93)
	at com.sheplers.support.Log.fail(Log.java:514)
	at com.sheplers.support.Log.assertThat(Log.java:692)
	at com.sheplers.testscripts.productsection.ProductReviewSection.TC_SHEPLERS_PRS_002(ProductReviewSection.java:156)
	at sun.reflect.NativeMethodAccessorImpl.invoke0(Native Method)
	at sun.reflect.NativeMethodAccessorImpl.invoke(Unknown Source)
	at sun.reflect.DelegatingMethodAccessorImpl.invoke(Unknown Source)
	at java.lang.reflect.Method.invoke(Unknown Source)
	at org.testng.internal.MethodInvocationHelper.invokeMethod(MethodInvocationHelper.java:108)
	at org.testng.internal.Invoker.invokeMethod(Invoker.java:661)
	at org.testng.internal.Invoker.invokeTestMethod(Invoker.java:869)
	at org.testng.internal.TestMethodWithDataProviderMethodWorker.call(TestMethodWithDataProviderMethodWorker.java:75)
	at org.testng.internal.TestMethodWithDataProviderMethodWorker.call(TestMethodWithDataProviderMethodWorker.java:14)
	at java.util.concurrent.FutureTask.run(Unknown Source)
	at java.util.concurrent.Executors$RunnableAdapter.call(Unknown Source)
	at java.util.concurrent.FutureTask.run(Unknown Source)
	at java.util.concurrent.ThreadPoolExecutor.runWorker(Unknown Source)
	at java.util.concurrent.ThreadPoolExecutor$Worker.run(Unknown Source)
	at java.lang.Thread.run(Unknown Source)
]]>
    </failure>
  </testcase> <!-- TC_SHEPLERS_PRS_002 -->
  <testcase name="TC_SHEPLERS_PRS_006" time="70.330" classname="com.sheplers.testscripts.productsection.ProductReviewSection"/>
</testsuite> <!-- com.sheplers.testscripts.productsection.ProductReviewSection -->
